Workbook
Name DateMin: MIN(Données!$A$2:$A$2107)
Name DateMax: MAX(Données!$A$2:$A$2107)

Sheet Synthèse
A1: Ventes de la pharmacie : synthèse pour mieux commander
A2: Question du client : anticiper la demande. Quels médicaments, quels jours, quelles périodes de l'année ?
B4: Aller à : | C4: Ventes ▶ | D4: Calendrier ▶ | E4: Conseils ▶ | F4: Questions ▶ | G4: Médicaments ▶ | H4: Méthode ▶
C5: Statistiques ▶ | D5: État des données ▶ | E5: Données ▶ | F5: Prévision ▶
A7: À PRÉPARER POUR OCTOBRE
A8: À renforcer | C8: Paracétamol, Asthme et BPCO
A9: À alléger | C9: Antihistaminiques (allergies)
A11: D'OÙ VIENNENT LES CHIFFRES
A12: ① Une seule source : l'export journalier. Les exports horaire et hebdomadaire disent exactement la même chose. ② Aucune vente corrigée : ni case vide, ni doublon, ni valeur négative sur 2106 jours. | C12: 31 / 70 | D12: mois où l'export mensuel annonce plus de ventes que les jours. Il est écarté : les mois sont recalculés à partir des jours. | H12: Voir le détail ▶
A13: Portée : 68 mois complets, de 02/2014 à 09/2019 (mois incomplets exclus des moyennes : 01/2014, 10/2019). L'unité des quantités n'est pas documentée par le logiciel de caisse : chaque groupe est comparé à lui-même dans le temps, jamais aux autres.
A15: LES CONCLUSIONS ET LES CHIFFRES QUI LES PROUVENT
A16: N° | B16: Conclusion | C16: Chiffre | D16: Ce que c'est | E16: Comparé à | F16: Ce que c'est | G16: Peut-on s'y fier ? | H16: Voir la preuve
A17: 1 | B17: Antihistaminiques (allergies) : forte saison. 3,5 fois plus de ventes en mai qu'en décembre. | C17: 1,75 | D17: Indice de mai (1 = mois moyen du groupe) | E17: 0,50 | F17: Indice de décembre | G17: Oui : creux en décembre 4 années sur 4 | H17: Calendrier ▶
A18: 2 | B18: Asthme et BPCO : forte saison. 2,8 fois plus de ventes en décembre qu'en juillet. | C18: 1,52 | D18: Indice de décembre (1 = mois moyen du groupe) | E18: 0,54 | F18: Indice de juillet | G18: Oui : creux en juillet 4 années sur 4 | H18: Calendrier ▶
A19: 3 | B19: Paracétamol : forte saison. 2,4 fois plus de ventes en janvier qu'en juillet. | C19: 1,57 | D19: Indice de janvier (1 = mois moyen du groupe) | E19: 0,65 | F19: Indice de juillet | G19: Oui : creux en juillet 4 années sur 4 | H19: Calendrier ▶
A20: 4 | B20: Asthme et BPCO : la demande monte, +28% en un an. | C20: 247 | D20: Ventes moyennes par mois, 12 derniers mois complets | E20: 194 | F20: Ventes moyennes par mois, 12 mois précédents | G20: À suivre : une seule année de recul | H20: Conseils ▶
A21: 5 | B21: Anti-inflammatoires type diclofénac, Aspirine et dérivés, Anxiolytiques : demande régulière toute l'année, stock constant. | C21: 0,29 | D21: Plus grand écart d'indice entre mois fort et mois faible (ces groupes) | E21: 1,25 | F21: Même écart pour antihistaminiques (allergies) | G21: Oui | H21: Calendrier ▶
A22: 6 | B22: Somnifères et sédatifs : ventes rares, aucune saison fiable. Stock minimal, réassort à la demande. | C22: 68% | D22: Jours sans aucune vente | E22: 0% | F22: Jours sans vente, paracétamol | G22: Oui | H22: Statistiques ▶
A23: 7 | B23: Anxiolytiques : nettement moins de ventes le dimanche. | C23: 5,7 | D23: Ventes moyennes un dimanche | E23: 9,4 | F23: Ventes moyennes un autre jour | G23: Oui : moyenne sur 301 dimanches | H23: Statistiques ▶
A24: 8 | B24: L'export mensuel ne concorde pas avec les ventes jour par jour : il n'est pas utilisé. | C24: 31 | D24: Mois en écart | E24: 70 | F24: Mois dans l'export | G24: À signaler à l'éditeur du logiciel de caisse | H24: État des données ▶
A25: 9 | B25: Peut-on prévoir les ventes du mois suivant (10/2019) ? Oui pour 5 groupes sur 8, dont le paracétamol (la moitié des ventes). | C25: 13,0 % | D25: Erreur moyenne de notre prévision, paracétamol (21 mois testés) | E25: 20,4 % | F25: Erreur de la meilleure prévision naïve | G25: Oui : testé sur 21 mois non utilisés pour construire la prévision | H25: Prévision ▶
B27: LÉGENDE
B28: Vert | C28: Conclusion solide : elle se répète d'une année à l'autre.
B29: Rose | C29: Point à surveiller ou à faire confirmer.
B30: Bleu | C30: Information, ou réponse pas encore établie.
A32: TRAITEMENT DES DONNÉES : CE QUI A ÉTÉ VÉRIFIÉ
B33: Point vérifié | C33: Résultat | D33: Constat | G33: Décision
B34: Qualité de chaque fichier | C34: OK | D34: Aucune case vide, aucune date en double, aucune quantité négative | G34: Aucune correction nécessaire
B35: Jours et heures manquants | C35: OK | D35: 0 jour absent, 0 heure absente | G35: Historique continu, utilisable tel quel
B36: Horaire comparé au journalier | C36: OK | D36: 0 jour(s) en écart sur 2106 | G36: L'horaire sert uniquement aux profils par heure
B37: Journalier comparé à l'hebdomadaire | C37: OK | D37: 0 semaine(s) en écart sur 302 | G37: L'hebdomadaire n'apporte rien de plus : non utilisé
B38: Journalier comparé au mensuel | C38: À noter | D38: 31 mois en écart sur 70 | G38: Mensuel écarté ; les mois sont recalculés à partir des jours
B39: Mois incomplets | C39: À noter | D39: 01/2014, 10/2019 | G39: Exclus des moyennes mensuelles, conservés dans l'onglet Ventes
B40: Colonnes Year, Month, Hour, Weekday Name | C40: À noter | D40: Redondantes avec la date ; « Hour » du journalier est une somme sans signification | G40: Ignorées et recalculées à partir de la date
B41: Unité des quantités | C41: À noter | D41: Non documentée ; les quantités ont des décimales | G41: Les groupes ne sont jamais additionnés ni comparés entre eux
B42: Valeurs de vente | C42: OK | D42: Aucune erreur de saisie démontrable | G42: Aucune vente modifiée ni supprimée
A43: Conclusion du traitement : les données sont utilisables telles quelles. Une seule source est retenue (le journalier), un export est écarté (le mensuel), et aucune vente n'a été modifiée.
A45: CE QUE LES CHIFFRES PEUVENT DIRE, ET CE QU'ILS NE PEUVENT PAS DIRE
B46: Question | C46: Réponse | D46: Pourquoi
B47: Quel est le niveau habituel des ventes d'un groupe ? | C47: OUI | D47: Ventes connues jour par jour sur près de six ans.
...

Sheet Ventes
A1: Ventes sur un jour ou une période
A2: Modifiez les cases jaunes. Pour un seul jour, mettez la même date au début et à la fin. Données disponibles du 02/01/2014 au 08/10/2019.
A3: ◀ Accueil
A5: Date de début | B5: 43739
A6: Date de fin | B6: 43746
A7: Nombre de jours | B7: =IF($B$6<$B$5,"Fin avant le début",$B$6-$B$5+1)
A9: Groupe | B9: Afficher ? | C9: Ventes sur la période | D9: Moyenne par jour | E9: Même période un an plus tôt | F9: Évolution
A10: Anti-inflammatoires type diclofénac | B10: OUI | C10: =IF($B10="OUI",SUMIFS(Données!$B$2:$B$2107,Données!$A$2:$A$2107,">="&$B$5,Données!$A$2:$A$2107,"<="&$B$6),"") | D10: =IF(AND($B10="OUI",ISNUMBER($B$7)),C10/$B$7,"") | E10: =IF($B10="OUI",SUMIFS(Données!$B$2:$B$2107,Données!$A$2:$A$2107,">="&EDATE($B$5,-12),Données!$A$2:$A$2107,"<="&EDATE($B$6,-12)),"") | F10: =IF(AND($B10="OUI",N(E10)>0),C10/E10-1,"")
A11: Anti-inflammatoires type ibuprofène | B11: OUI | C11: =IF($B11="OUI",SUMIFS(Données!$C$2:$C$2107,Données!$A$2:$A$2107,">="&$B$5,Données!$A$2:$A$2107,"<="&$B$6),"") | D11: =IF(AND($B11="OUI",ISNUMBER($B$7)),C11/$B$7,"") | E11: =IF($B11="OUI",SUMIFS(Données!$C$2:$C$2107,Données!$A$2:$A$2107,">="&EDATE($B$5,-12),Données!$A$2:$A$2107,"<="&EDATE($B$6,-12)),"") | F11: =IF(AND($B11="OUI",N(E11)>0),C11/E11-1,"")
A12: Aspirine et dérivés | B12: OUI | C12: =IF($B12="OUI",SUMIFS(Données!$D$2:$D$2107,Données!$A$2:$A$2107,">="&$B$5,Données!$A$2:$A$2107,"<="&$B$6),"") | D12: =IF(AND($B12="OUI",ISNUMBER($B$7)),C12/$B$7,"") | E12: =IF($B12="OUI",SUMIFS(Données!$D$2:$D$2107,Données!$A$2:$A$2107,">="&EDATE($B$5,-12),Données!$A$2:$A$2107,"<="&EDATE($B$6,-12)),"") | F12: =IF(AND($B12="OUI",N(E12)>0),C12/E12-1,"")
A13: Paracétamol | B13: OUI | C13: =IF($B13="OUI",SUMIFS(Données!$E$2:$E$2107,Données!$A$2:$A$2107,">="&$B$5,Données!$A$2:$A$2107,"<="&$B$6),"") | D13: =IF(AND($B13="OUI",ISNUMBER($B$7)),C13/$B$7,"") | E13: =IF($B13="OUI",SUMIFS(Données!$E$2:$E$2107,Données!$A$2:$A$2107,">="&EDATE($B$5,-12),Données!$A$2:$A$2107,"<="&EDATE($B$6,-12)),"") | F13: =IF(AND($B13="OUI",N(E13)>0),C13/E13-1,"")
A14: Anxiolytiques | B14: OUI | C14: =IF($B14="OUI",SUMIFS(Données!$F$2:$F$2107,Données!$A$2:$A$2107,">="&$B$5,Données!$A$2:$A$2107,"<="&$B$6),"") | D14: =IF(AND($B14="OUI",ISNUMBER($B$7)),C14/$B$7,"") | E14: =IF($B14="OUI",SUMIFS(Données!$F$2:$F$2107,Données!$A$2:$A$2107,">="&EDATE($B$5,-12),Données!$A$2:$A$2107,"<="&EDATE($B$6,-12)),"") | F14: =IF(AND($B14="OUI",N(E14)>0),C14/E14-1,"")
A15: Somnifères et sédatifs | B15: OUI | C15: =IF($B15="OUI",SUMIFS(Données!$G$2:$G$2107,Données!$A$2:$A$2107,">="&$B$5,Données!$A$2:$A$2107,"<="&$B$6),"") | D15: =IF(AND($B15="OUI",ISNUMBER($B$7)),C15/$B$7,"") | E15: =IF($B15="OUI",SUMIFS(Données!$G$2:$G$2107,Données!$A$2:$A$2107,">="&EDATE($B$5,-12),Données!$A$2:$A$2107,"<="&EDATE($B$6,-12)),"") | F15: =IF(AND($B15="OUI",N(E15)>0),C15/E15-1,"")
A16: Asthme et BPCO | B16: OUI | C16: =IF($B16="OUI",SUMIFS(Données!$H$2:$H$2107,Données!$A$2:$A$2107,">="&$B$5,Données!$A$2:$A$2107,"<="&$B$6),"") | D16: =IF(AND($B16="OUI",ISNUMBER($B$7)),C16/$B$7,"") | E16: =IF($B16="OUI",SUMIFS(Données!$H$2:$H$2107,Données!$A$2:$A$2107,">="&EDATE($B$5,-12),Données!$A$2:$A$2107,"<="&EDATE($B$6,-12)),"") | F16: =IF(AND($B16="OUI",N(E16)>0),C16/E16-1,"")
A17: Antihistaminiques (allergies) | B17: OUI | C17: =IF($B17="OUI",SUMIFS(Données!$I$2:$I$2107,Données!$A$2:$A$2107,">="&$B$5,Données!$A$2:$A$2107,"<="&$B$6),"") | D17: =IF(AND($B17="OUI",ISNUMBER($B$7)),C17/$B$7,"") | E17: =IF($B17="OUI",SUMIFS(Données!$I$2:$I$2107,Données!$A$2:$A$2107,">="&EDATE($B$5,-12),Données!$A$2:$A$2107,"<="&EDATE($B$6,-12)),"") | F17: =IF(AND($B17="OUI",N(E17)>0),C17/E17-1,"")
A19: Comparez un groupe à lui-même dans le temps, pas les groupes entre eux : l'unité des quantités n'est pas connue.
A21: Voir le calendrier des saisons ▶ | C21: Lire les conseils de commande ▶
A23: LÉGENDE
A24: Case jaune | B24: À vous de la modifier : les deux dates, et OUI ou NON pour chaque groupe.
A25: Case blanche | B25: Résultat calculé automatiquement : ne pas modifier.
A26: Case ▶ | B26: Bouton cliquable. Sa couleur est celle de l'onglet qu'il ouvre.

Sheet Calendrier
A1: Calendrier des saisons
A2: Pour chaque groupe, les mois où il se vend plus ou moins que d'habitude.
A3: ◀ Accueil
A5: LÉGENDE
A6: Mois fort | B6: Ventes au moins 15% au-dessus d'un mois moyen du groupe : renforcer le stock.
A7: Mois creux | B7: Ventes au moins 15% en dessous d'un mois moyen : alléger le stock.
A8: Mois normal | B8: Ventes proches de la moyenne. Le chiffre 1,00 correspond à un mois moyen du groupe.
A10: LE CALENDRIER
A11: Groupe | B11: Janvier | C11: Février | D11: Mars | E11: Avril | F11: Mai | G11: Juin | H11: Juillet | I11: Août | J11: Septembre | K11: Octobre | L11: Novembre | M11: Décembre
A12: Anti-inflammatoires type diclofénac | B12: 1.1 | C12: 0.9 | D12: 0.98 | E12: 1.02 | F12: 0.97 | G12: 0.91 | H12: 1.04 | I12: 1.08 | J12: 0.97 | K12: 0.99 | L12: 1.01 | M12: 1.05
A13: Anti-inflammatoires type ibuprofène | B13: 1.27 | C13: 1.09 | D13: 1 | E13: 0.93 | F13: 0.96 | G13: 0.89 | H13: 0.97 | I13: 0.93 | J13: 0.99 | K13: 1 | L13: 0.95 | M13: 1.08
A14: Aspirine et dérivés | B14: 1.15 | C14: 1.13 | D14: 1.05 | E14: 0.96 | F14: 0.98 | G14: 0.96 | H14: 0.92 | I14: 0.91 | J14: 0.86 | K14: 1.06 | L14: 1.07 | M14: 1
A15: Paracétamol | B15: 1.57 | C15: 1.11 | D15: 1 | E15: 0.87 | F15: 0.78 | G15: 0.67 | H15: 0.65 | I15: 0.69 | J15: 1.04 | K15: 1.42 | L15: 1.06 | M15: 1.39
A16: Anxiolytiques | B16: 1.15 | C16: 0.94 | D16: 0.96 | E16: 0.91 | F16: 0.87 | G16: 0.89 | H16: 0.96 | I16: 1.05 | J16: 1.04 | K16: 1.1 | L16: 1.04 | M16: 1.16
A17: Somnifères et sédatifs | B17: 1.22 | C17: 0.85 | D17: 1.08 | E17: 0.81 | F17: 1.07 | G17: 0.99 | H17: 0.83 | I17: 1.07 | J17: 0.88 | K17: 0.88 | L17: 1.13 | M17: 1.27
A18: Asthme et BPCO | B18: 1.42 | C18: 1.13 | D18: 1.14 | E18: 1.03 | F18: 0.92 | G18: 0.77 | H18: 0.54 | I18: 0.56 | J18: 0.77 | K18: 1.34 | L18: 1.1 | M18: 1.52
A19: Antihistaminiques (allergies) | B19: 0.54 | C19: 0.53 | D19: 1.1 | E19: 1.64 | F19: 1.75 | G19: 1.48 | H19: 1.16 | I19: 0.93 | J19: 0.86 | K19: 0.69 | L19: 0.52 | M19: 0.5
A22: À PRÉPARER POUR LES TROIS PROCHAINS MOIS
A23: Mois | B23: À renforcer | H23: À alléger
A24: Octobre | B24: Paracétamol, Asthme et BPCO | H24: Antihistaminiques (allergies)
A25: Novembre | B25: rien de particulier | H25: Antihistaminiques (allergies)
A26: Décembre | B26: Paracétamol, Anxiolytiques, Asthme et BPCO | H26: Antihistaminiques (allergies)
A29: PEUT-ON S'Y FIER ? NOMBRE D'ANNÉES, SUR 4 (2015 À 2018), OÙ LE MOIS A ÉTÉ SOUS LA MOYENNE DE SON ANNÉE
A30: Groupe | B30: Janvier | C30: Février | D30: Mars | E30: Avril | F30: Mai | G30: Juin | H30: Juillet | I30: Août | J30: Septembre | K30: Octobre | L30: Novembre | M30: Décembre
A31: Anti-inflammatoires type diclofénac | B31: 2 sur 4 | C31: 4 sur 4 | D31: 3 sur 4 | E31: 2 sur 4 | F31: 2 sur 4 | G31: 4 sur 4 | H31: 2 sur 4 | I31: 1 sur 4 | J31: 2 sur 4 | K31: 2 sur 4 | L31: 2 sur 4 | M31: 1 sur 4
A32: Anti-inflammatoires type ibuprofène | B32: 1 sur 4 | C32: 1 sur 4 | D32: 2 sur 4 | E32: 3 sur 4 | F32: 3 sur 4 | G32: 4 sur 4 | H32: 2 sur 4 | I32: 3 sur 4 | J32: 2 sur 4 | K32: 1 sur 4 | L32: 2 sur 4 | M32: 0 sur 4
A33: Aspirine et dérivés | B33: 0 sur 4 | C33: 2 sur 4 | D33: 1 sur 4 | E33: 3 sur 4 | F33: 3 sur 4 | G33: 3 sur 4 | H33: 4 sur 4 | I33: 4 sur 4 | J33: 4 sur 4 | K33: 2 sur 4 | L33: 1 sur 4 | M33: 2 sur 4
A34: Paracétamol | B34: 0 sur 4 | C34: 2 sur 4 | D34: 1 sur 4 | E34: 3 sur 4 | F34: 4 sur 4 | G34: 4 sur 4 | H34: 4 sur 4 | I34: 4 sur 4 | J34: 2 sur 4 | K34: 0 sur 4 | L34: 1 sur 4 | M34: 0 sur 4
A35: Anxiolytiques | B35: 2 sur 4 | C35: 4 sur 4 | D35: 3 sur 4 | E35: 2 sur 4 | F35: 4 sur 4 | G35: 3 sur 4 | H35: 2 sur 4 | I35: 1 sur 4 | J35: 2 sur 4 | K35: 1 sur 4 | L35: 4 sur 4 | M35: 2 sur 4
A36: Somnifères et sédatifs | B36: 1 sur 4 | C36: 3 sur 4 | D36: 3 sur 4 | E36: 3 sur 4 | F36: 2 sur 4 | G36: 3 sur 4 | H36: 3 sur 4 | I36: 3 sur 4 | J36: 2 sur 4 | K36: 2 sur 4 | L36: 0 sur 4 | M36: 1 sur 4
A37: Asthme et BPCO | B37: 1 sur 4 | C37: 2 sur 4 | D37: 1 sur 4 | E37: 1 sur 4 | F37: 4 sur 4 | G37: 2 sur 4 | H37: 4 sur 4 | I37: 4 sur 4 | J37: 4 sur 4 | K37: 0 sur 4 | L37: 1 sur 4 | M37: 0 sur 4
A38: Antihistaminiques (allergies) | B38: 4 sur 4 | C38: 4 sur 4 | D38: 2 sur 4 | E38: 0 sur 4 | F38: 0 sur 4 | G38: 0 sur 4 | H38: 1 sur 4 | I38: 2 sur 4 | J38: 4 sur 4 | K38: 4 sur 4 | L38: 4 sur 4 | M38: 4 sur 4
A40: Voir les ventes d'une période ▶

Sheet Conseils
A1: Conseils de commande par groupe
A2: Évolution sur un an : 10/2018 à 09/2019 comparé à 10/2017 à 09/2018.
A3: ◀ Accueil
A5: Groupe | B5: Code | C5: Conseil de commande | D5: Mois forts | E5: Mois creux | F5: Évolution sur un an | G5: Saisonnalité | H5: Jour le plus fort | I5: Jour le plus faible
A6: Anti-inflammatoires type diclofénac | B6: M01AB | C6: Demande régulière toute l'année : stock constant. Demande stable sur un an. | D6: aucun | E6: aucun | F6: +9% | G6: Faible | H6: Samedi | I6: Jeudi
A7: Anti-inflammatoires type ibuprofène | B7: M01AE | C7: Renforcer le stock avant janvier. Demande stable sur un an. | D7: Janvier | E7: aucun | F7: +3% | G7: Modérée | H7: Dimanche | I7: Mardi
A8: Aspirine et dérivés | B8: N02BA | C8: Demande régulière toute l'année : stock constant. Demande stable sur un an. | D8: Janvier | E8: aucun | F8: -4% | G8: Faible | H8: Mardi | I8: Dimanche
A9: Paracétamol | B9: N02BE | C9: Renforcer le stock avant janvier, octobre, décembre ; l'alléger en mai, juin, juillet, août. Demande stable sur un an. | D9: Janvier, Octobre, Décembre | E9: Mai, Juin, Juillet, Août | F9: +2% | G9: Forte | H9: Dimanche | I9: Mercredi
A10: Anxiolytiques | B10: N05B | C10: Demande régulière toute l'année : stock constant. Demande stable sur un an. | D10: Janvier, Décembre | E10: aucun | F10: +1% | G10: Faible | H10: Mercredi | I10: Dimanche
A11: Somnifères et sédatifs | B11: N05C | C11: Ventes rares (aucune vente 68% des jours) : stock minimal, réassort à la demande. Demande en hausse sur un an (+36%) : prévoir plus que l'an dernier. | D11: Janvier, Décembre | E11: Février, Avril, Juillet | F11: +36% | G11: Non significative (ventes rares) | H11: Vendredi | I11: Dimanche
A12: Asthme et BPCO | B12: R03 | C12: Renforcer le stock avant janvier, octobre, décembre ; l'alléger en juin, juillet, août, septembre. Demande en hausse sur un an (+28%) : prévoir plus que l'an dernier. | D12: Janvier, Octobre, Décembre | E12: Juin, Juillet, Août, Septembre | F12: +28% | G12: Forte | H12: Lundi | I12: Dimanche
A13: Antihistaminiques (allergies) | B13: R06 | C13: Renforcer le stock avant avril, mai, juin, juillet ; l'alléger en janvier, février, octobre, novembre, décembre. Demande stable sur un an. | D13: Avril, Mai, Juin, Juillet | E13: Janvier, Février, Octobre, Novembre, Décembre | F13: +7% | G13: Forte | H13: Samedi | I13: Jeudi

Sheet Prévision
A1: Peut-on prévoir les ventes du mois suivant ?
A2: Question du manager : prévoir, pour chaque groupe, le mois qui suit le dernier mois complet (septembre 2019), donc octobre 2019.
A3: ◀ Accueil
A5: LA RÉPONSE
A6: Oui, pour 5 groupes sur 8, dont le paracétamol qui représente la moitié des ventes. Non pour : Anti-inflammatoires type ibuprofène (M01AE), Asthme et BPCO (R03). Gain trop faible pour : Aspirine et dérivés (N02BA).
A8: COMMENT C'EST TESTÉ
A9: 1. On fait comme si on était dans le passé : avec les seules ventes connues jusqu'à décembre 2017, on prévoit janvier 2018, puis on compare au vrai chiffre. On répète chaque mois jusqu'à septembre 2019 : 21 prévisions testées.
A10: 2. Deux prévisions « naïves », que n'importe qui ferait sans nous : le mois prochain = le mois dernier ; le mois prochain = le même mois l'an dernier.
A11: 3. Deux méthodes à nous : la moyenne des 3 derniers mois ; le niveau des 12 derniers mois corrigé de l'effet de saison du mois (« Saison x niveau »).
A12: 4. Un groupe est jugé prévisible si notre meilleure méthode fait au moins 2 points d'erreur de moins que la meilleure naïve. En dessous, la différence peut être due au hasard.
A14: RÉSULTAT DU TEST : ERREUR MOYENNE EN % (plus c'est bas, mieux c'est)
A15: Groupe | B15: Code | C15: Naïve : mois dernier | D15: Naïve : même mois an dernier | E15: Moyenne 3 derniers mois | F15: Saison x niveau | G15: Meilleure naïve | H15: Notre meilleure | I15: Gain (points) | J15: Prévisible ?
A16: Anti-inflammatoires type diclofénac | B16: M01AB | C16: 0.109 | D16: 0.099 | E16: 0.098 | F16: 0.075 | G16: 0.099 | H16: 0.075 | I16: 2.4 | J16: Oui
A17: Anti-inflammatoires type ibuprofène | B17: M01AE | C17: 0.145 | D17: 0.125 | E17: 0.134 | F17: 0.127 | G17: 0.125 | H17: 0.127 | I17: -0.2 | J17: Non
A18: Aspirine et dérivés | B18: N02BA | C18: 0.108 | D18: 0.131 | E18: 0.104 | F18: 0.107 | G18: 0.108 | H18: 0.104 | I18: 0.4 | J18: Gain marginal
A19: Paracétamol | B19: N02BE | C19: 0.207 | D19: 0.204 | E19: 0.298 | F19: 0.13 | G19: 0.204 | H19: 0.13 | I19: 7.4 | J19: Oui
A20: Anxiolytiques | B20: N05B | C20: 0.144 | D20: 0.221 | E20: 0.115 | F20: 0.182 | G20: 0.144 | H20: 0.115 | I20: 2.9 | J20: Oui
A21: Somnifères et sédatifs | B21: N05C | C21: 0.398 | D21: 0.502 | E21: 0.338 | F21: 0.339 | G21: 0.398 | H21: 0.338 | I21: 6 | J21: Oui
A22: Asthme et BPCO | B22: R03 | C22: 0.279 | D22: 0.315 | E22: 0.394 | F22: 0.3 | G22: 0.279 | H22: 0.3 | I22: -2.1 | J22: Non
A23: Antihistaminiques (allergies) | B23: R06 | C23: 0.304 | D23: 0.255 | E23: 0.38 | F23: 0.19 | G23: 0.255 | H23: 0.19 | I23: 6.5 | J23: Oui
A25: PRÉVISION POUR OCTOBRE 2019
A26: Groupe | B26: Code | C26: Prévision 10/2019 | D26: Réel 09/2019 | E26: Réel 10/2018 | F26: Méthode utilisée
A27: Anti-inflammatoires type diclofénac | B27: M01AB | C27: 161 | D27: 161 | E27: 145 | F27: Saison x niveau (erreur moyenne 7.5 % sur 21 mois)
A28: Anti-inflammatoires type ibuprofène | B28: M01AE | C28: Pas fiable | D28: 111 | E28: 129 | F28: Aucune méthode ne bat la prévision naïve : se fier au calendrier des saisons
A29: Aspirine et dérivés | B29: N02BA | C29: Pas fiable | D29: 94 | E29: 76 | F29: Aucune méthode ne bat la prévision naïve : se fier au calendrier des saisons
A30: Paracétamol | B30: N02BE | C30: 1307 | D30: 984 | E30: 1129 | F30: Saison x niveau (erreur moyenne 13.0 % sur 21 mois)
A31: Anxiolytiques | B31: N05B | C31: 238 | D31: 228 | E31: 287 | F31: Moyenne 3 derniers mois (erreur moyenne 11.5 % sur 21 mois)
A32: Somnifères et sédatifs | B32: N05C | C32: 21 | D32: 16 | E32: 25 | F32: Moyenne 3 derniers mois (erreur moyenne 33.8 % sur 21 mois)
A33: Asthme et BPCO | B33: R03 | C33: Pas fiable | D33: 121 | E33: 327 | F33: Aucune méthode ne bat la prévision naïve : se fier au calendrier des saisons
A34: Antihistaminiques (allergies) | B34: R06 | C34: 75 | D34: 109 | E34: 77 | F34: Saison x niveau (erreur moyenne 19.0 % sur 21 mois)
A36: Mise à jour automatique par classeur.ipynb avec l'export du 08/10/2019. Octobre 2019 ne peut pas encore servir à vérifier la prévision : il n'est pas terminé dans l'export.

Sheet Questions
A1: Questions fréquentes
A3: ◀ Accueil
A5: Question | B5: Réponse
A6: En quelle unité sont les quantités ? | B6: On ne le sait pas : le logiciel de caisse ne le documente pas. Les quantités ont des décimales, ce ne sont donc pas des boîtes entières.
A7: Puis-je additionner ou comparer deux groupes ? | B7: Non. Faute d'unité connue, rien ne dit qu'une unité d'un groupe vaut une unité d'un autre. Comparez un groupe à lui-même dans le temps.
A8: Que contient exactement chaque groupe ? | B8: L'export regroupe les ventes par code ATC, la classification internationale des médicaments tenue par l'OMS. Le nom officiel de chaque groupe et des exemples de substances sont dans l'onglet Médicaments.
A9: Puis-je connaître le chiffre d'affaires ou la marge ? | B9: Non, l'export ne contient aucun prix.
A10: Pourquoi les mois de ce classeur ne correspondent-ils pas à mon export mensuel ? | B10: L'export mensuel ne concorde pas avec les ventes jour par jour sur 31 mois (liste dans l'onglet État des données). Les exports horaire, journalier et hebdomadaire concordent entre eux : les mois sont donc recalculés à partir des jours.
A11: Pourquoi certains mois manquent-ils dans les statistiques mensuelles ? | B11: Les mois incomplets sont exclus pour ne pas fausser les moyennes : 01/2014, 10/2019. Leurs jours restent disponibles dans l'onglet Ventes.
A12: Comment voir les ventes d'un seul jour ? | B12: Dans l'onglet Ventes, mettez la même date en début et en fin.
A13: Pourquoi la colonne Évolution est-elle vide ? | B13: Soit le groupe est sur NON, soit il n'y a aucune vente à la même période un an plus tôt (par exemple pour une période de 2014).
A14: Quelles dates puis-je choisir ? | B14: Du 02/01/2014 au 08/10/2019. Une date en dehors est refusée.
A15: Que veulent dire les couleurs du calendrier ? | B15: Orange : mois fort, au moins 15% au-dessus d'un mois moyen du groupe. Bleu : mois creux, au moins 15% en dessous.
A16: Puis-je modifier l'onglet Données ? | B16: Il vaut mieux ne pas y toucher : l'onglet Ventes lit ses chiffres dedans. Ce sont les ventes telles qu'exportées, sans aucune modification.
... A18: Peut-on prévoir les ventes du mois prochain ? | B18: Oui pour 5 groupes sur 8 : notre prévision fait mieux que la méthode la plus simple, testée sur 21 mois. Pas pour l'asthme (R03) ni l'ibuprofène (M01AE). Détail dans l'onglet Prévision.

Sheet Médicaments
A1: Ce que contient chaque groupe
A2: Source : classification ATC de l'Organisation mondiale de la santé.
A3: ◀ Accueil
A5: Code ATC | B5: Nom utilisé dans ce classeur | C5: Nom officiel OMS (anglais) | D5: Traduction française | E5: Famille | F5: Exemples ou sous-groupes | G5: Source
A6: M01AB | B6: Anti-inflammatoires type diclofénac | C6: Acetic acid derivatives and related substances | D6: Dérivés de l'acide acétique et substances apparentées | E6: Système musculo-squelettique > Anti-inflammatoires et antirhumatismaux non stéroïdiens | F6: diclofénac, indométacine, kétorolac, acéclofénac, étodolac | G6: https://atcddd.fhi.no/atc_ddd_index/?code=M01AB
A7: M01AE | B7: Anti-inflammatoires type ibuprofène | C7: Propionic acid derivatives | D7: Dérivés de l'acide propionique | E7: Système musculo-squelettique > Anti-inflammatoires et antirhumatismaux non stéroïdiens | F7: ibuprofène, naproxène, kétoprofène, flurbiprofène, dexkétoprofène | G7: https://atcddd.fhi.no/atc_ddd_index/?code=M01AE
A8: N02BA | B8: Aspirine et dérivés | C8: Salicylic acid and derivatives | D8: Acide salicylique et dérivés | E8: Système nerveux > Analgésiques > Autres analgésiques et antipyrétiques | F8: acide acétylsalicylique (aspirine), diflunisal, carbasalate calcique | G8: https://atcddd.fhi.no/atc_ddd_index/?code=N02BA
A9: N02BE | B9: Paracétamol | C9: Anilides | D9: Anilides | E9: Système nerveux > Analgésiques > Autres analgésiques et antipyrétiques | F9: paracétamol, propacétamol, paracétamol en association | G9: https://atcddd.fhi.no/atc_ddd_index/?code=N02BE
A10: N05B | B10: Anxiolytiques | C10: Anxiolytics | D10: Anxiolytiques | E10: Système nerveux > Psycholeptiques | F10: sous-groupes : dérivés des benzodiazépines (N05BA), dérivés du diphénylméthane (N05BB), carbamates (N05BC), autres anxiolytiques (N05BX) | G10: https://atcddd.fhi.no/atc_ddd_index/?code=N05B
A11: N05C | B11: Somnifères et sédatifs | C11: Hypnotics and sedatives | D11: Hypnotiques et sédatifs | E11: Système nerveux > Psycholeptiques | F11: sous-groupes : dérivés des benzodiazépines (N05CD), médicaments apparentés aux benzodiazépines (N05CF), agonistes des récepteurs de la mélatonine (N05CH), barbituriques (N05CA) | G11: https://atcddd.fhi.no/atc_ddd_index/?code=N05C
A12: R03 | B12: Asthme et BPCO | C12: Drugs for obstructive airway diseases | D12: Médicaments des syndromes obstructifs des voies aériennes | E12: Système respiratoire | F12: sous-groupes : adrénergiques inhalés (R03A), autres médicaments inhalés (R03B), adrénergiques à usage systémique (R03C), autres médicaments systémiques (R03D) | G12: https://atcddd.fhi.no/atc_ddd_index/?code=R03
A13: R06 | B13: Antihistaminiques (allergies) | C13: Antihistamines for systemic use | D13: Antihistaminiques à usage systémique | E13: Système respiratoire | F13: sous-groupe unique R06A, subdivisé selon la structure chimique | G13: https://atcddd.fhi.no/atc_ddd_index/?code=R06

Sheet Méthode
A1: Méthode : comment chaque chiffre est obtenu
A3: ◀ Accueil
A5: Étape | B5: Ce que fait le programme | C5: Comment le refaire à la main dans Excel
A6: 1. Lire les exports | B6: Ouvre les 4 fichiers CSV et transforme la colonne « datum » en dates. Format mois/jour/année, sauf le Monthly en année-mois-jour. | C6: Données > À partir d'un fichier texte/CSV. Pour la colonne datum, choisir le type « Date » avec les paramètres régionaux Anglais (États-Unis), sinon le 2 janvier devient le 1er février.
A7: 2. Contrôler chaque export | B7: Compte les cases vides, les dates en double et les quantités négatives. Vérifie qu'aucun jour ni aucune heure ne manque. | C7: NB.VIDE sur la plage ; NB.SI(plage;"<0") ; pour les doublons, Mise en forme conditionnelle > Valeurs en double sur la colonne des dates ; pour les jours manquants, comparer (dernière date - première date + 1) au nombre de lignes.
A8: 3. Comparer les exports entre eux | B8: Additionne les heures par jour, les jours par semaine et les jours par mois, puis compare au fichier correspondant. Un écart inférieur à 0,01 est un arrondi. | C8: SOMME.SI.ENS sur le Daily entre le premier et le dernier jour du mois, puis soustraire la valeur du Monthly.
A9: 4. Choisir l'export de référence | B9: Garde le Daily, écarte le Monthly, n'utilise le Hourly que pour les heures. | C9: Travailler uniquement à partir de l'onglet Données.
A10: 5. Recalculer année, mois, jour | B10: Ignore les colonnes Year, Month, Hour et Weekday Name des exports et les recalcule à partir de la date. | C10: ANNEE(date), MOIS(date), et TEXTE(date;"jjjj") pour le nom du jour.
A11: 6. Repérer les mois complets | B11: Un mois est complet si tous ses jours sont présents. Les autres sont exclus des statistiques mensuelles. | C11: NB.SI.ENS sur les dates du mois, comparé à JOUR(FIN.MOIS(date;0)).
A12: 7. Statistiques par groupe | B12: Moyenne, médiane, écart-type, maximum par jour ; coefficient de variation = écart-type / moyenne ; part des jours sans vente. | C12: MOYENNE, MEDIANE, ECARTYPE.STANDARD, MAX sur la colonne du groupe ; NB.SI(colonne;0)/NBVAL(colonne).
A13: 8. Saisonnalité | B13: Moyenne des ventes de chaque mois de l'année sur les mois complets. Indice = cette moyenne divisée par la moyenne de tous les mois complets. | C13: Sur le tableau des mois complets de l'onglet Statistiques : MOYENNE.SI sur le numéro du mois, puis division par MOYENNE de la colonne.
A14: 9. Calendrier et conseils | B14: Un mois est dit fort si son indice atteint 1.15, creux s'il descend à 0.85. La régularité compte, sur les années entières, combien de fois le mois est passé sous la moyenne de son année. L'évolution sur un an compare les 12 derniers mois complets aux 12 précédents. | C14: Mise en forme conditionnelle sur les indices ; pour l'évolution, SOMME des 12 derniers mois complets divisée par SOMME des 12 précédents, moins 1.
A15: 10. Jour de semaine et heure | B15: Moyenne des ventes par jour de la semaine (Daily) et par heure (Hourly). | C15: MOYENNE.SI(colonne Jour;"Lundi";colonne du groupe). Les heures demandent d'ouvrir le fichier Hourly.
A16: 11. Évolution par année | B16: Moyenne par jour pour chaque année, et non un total, car la première et la dernière année sont incomplètes. | C16: MOYENNE.SI(colonne Année;2018;colonne du groupe).
... A19: 14. Prévision du mois suivant | B19: Le script prevision.py se replace chaque mois de janvier 2018 à septembre 2019, prévoit le mois suivant avec 4 méthodes (2 naïves, 2 à nous) et compare au réel. Un groupe est prévisible si notre meilleure méthode bat la meilleure naïve d'au moins 2 points d'erreur. | C19: Pour un mois donné : MOYENNE des 3 mois précédents ; erreur = ABS(prévu - réel) / réel ; puis MOYENNE des erreurs sur les 21 mois. Comparer à la même erreur pour « mois dernier ».

Sheet Statistiques
A1: Statistiques détaillées
A2: Quantités dans l'unité du logiciel de caisse. Colonnes : codes des groupes (voir Médicaments).
A3: ◀ Accueil
A5: PAR GROUPE (VENTES PAR JOUR, PUIS PAR MOIS COMPLET)
A6: Groupe | B6: Nom | C6: Total | D6: Moyenne par jour | E6: Médiane par jour | F6: Écart-type par jour | G6: Coefficient de variation | H6: Maximum sur un jour | I6: Part des jours sans vente | J6: Moyenne par mois complet | K6: Mois le plus bas | L6: Mois le plus haut
A7: M01AB | B7: Anti-inflammatoires type diclofénac | C7: 10724 | D7: 5.09 | E7: 5 | F7: 2.71 | G7: 0.53 | H7: 17.3 | I7: 0.007 | J7: 155.1 | K7: 98.4 | L7: 211.1
A8: M01AE | B8: Anti-inflammatoires type ibuprofène | C8: 8330.8 | D8: 3.96 | E8: 3.68 | F8: 2.12 | G8: 0.54 | H8: 14.5 | I8: 0.005 | J8: 120.5 | K8: 88.3 | L8: 207.6
A9: N02BA | B9: Aspirine et dérivés | C9: 8189.7 | D9: 3.89 | E9: 3.5 | F9: 2.34 | G9: 0.6 | H9: 16 | I9: 0.026 | J9: 117.9 | K9: 75.2 | L9: 187
A10: N02BE | B10: Paracétamol | C10: 64151.6 | D10: 30.46 | E10: 27 | F10: 15.83 | G10: 0.52 | H10: 161 | I10: 0 | J10: 925.6 | K10: 479.4 | L10: 1822.8
A11: N05B | B11: Anxiolytiques | C11: 18613 | D11: 8.84 | E11: 8 | F11: 5.53 | G11: 0.63 | H11: 54.8 | I11: 0.009 | J11: 267.2 | K11: 135 | L11: 525
A12: N05C | B12: Somnifères et sédatifs | C12: 1249 | D12: 0.59 | E12: 0 | F12: 1.1 | G12: 1.85 | H12: 9 | I12: 0.682 | J12: 17.8 | K12: 5 | L12: 42
A13: R03 | B13: Asthme et BPCO | C13: 11745.1 | D13: 5.58 | E13: 4 | F13: 6.49 | G13: 1.16 | H13: 45 | I13: 0.225 | J13: 170.5 | K13: 37 | L13: 402
A14: R06 | B14: Antihistaminiques (allergies) | C14: 6164.5 | D14: 2.93 | E14: 2 | F14: 2.42 | G14: 0.83 | H14: 15 | I14: 0.115 | J14: 89.7 | K14: 34.6 | L14: 213
A17: INDICE SAISONNIER (1 = MOIS MOYEN DU GROUPE)
A18: Mois | B18: M01AB | C18: M01AE | D18: N02BA | E18: N02BE | F18: N05B | G18: N05C | H18: R03 | I18: R06
A19: Janvier | B19: 1.1 | C19: 1.27 | D19: 1.15 | E19: 1.57 | F19: 1.15 | G19: 1.22 | H19: 1.42 | I19: 0.54
A20: Février | B20: 0.9 | C20: 1.09 | D20: 1.13 | E20: 1.11 | F20: 0.94 | G20: 0.85 | H20: 1.13 | I20: 0.53
A21: Mars | B21: 0.98 | C21: 1 | D21: 1.05 | E21: 1 | F21: 0.96 | G21: 1.08 | H21: 1.14 | I21: 1.1
A22: Avril | B22: 1.02 | C22: 0.93 | D22: 0.96 | E22: 0.87 | F22: 0.91 | G22: 0.81 | H22: 1.03 | I22: 1.64
A23: Mai | B23: 0.97 | C23: 0.96 | D23: 0.98 | E23: 0.78 | F23: 0.87 | G23: 1.07 | H23: 0.92 | I23: 1.75
A24: Juin | B24: 0.91 | C24: 0.89 | D24: 0.96 | E24: 0.67 | F24: 0.89 | G24: 0.99 | H24: 0.77 | I24: 1.48
A25: Juillet | B25: 1.04 | C25: 0.97 | D25: 0.92 | E25: 0.65 | F25: 0.96 | G25: 0.83 | H25: 0.54 | I25: 1.16
A26: Août | B26: 1.08 | C26: 0.93 | D26: 0.91 | E26: 0.69 | F26: 1.05 | G26: 1.07 | H26: 0.56 | I26: 0.93
A27: Septembre | B27: 0.97 | C27: 0.99 | D27: 0.86 | E27: 1.04 | F27: 1.04 | G27: 0.88 | H27: 0.77 | I27: 0.86
A28: Octobre | B28: 0.99 | C28: 1 | D28: 1.06 | E28: 1.42 | F28: 1.1 | G28: 0.88 | H28: 1.34 | I28: 0.69
A29: Novembre | B29: 1.01 | C29: 0.95 | D29: 1.07 | E29: 1.06 | F29: 1.04 | G29: 1.13 | H29: 1.1 | I29: 0.52
A30: Décembre | B30: 1.05 | C30: 1.08 | D30: 1 | E30: 1.39 | F30: 1.16 | G30: 1.27 | H30: 1.52 | I30: 0.5
A33: VENTES MOYENNES DE CHAQUE MOIS DE L'ANNÉE
A34: Mois | B34: M01AB | C34: M01AE | D34: N02BA | E34: N02BE | F34: N05B | G34: N05C | H34: R03 | I34: R06
A35: Janvier | B35: 170.3 | C35: 152.8 | D35: 135.4 | E35: 1450.7 | F35: 307.8 | G35: 21.8 | H35: 241.6 | I35: 48.8
A36: Février | B36: 139.5 | C36: 131.2 | D36: 132.7 | E36: 1024.4 | F36: 250.7 | G36: 15.2 | H36: 191.9 | I36: 47.4
A37: Mars | B37: 152.3 | C37: 120.6 | D37: 123.8 | E37: 927.9 | F37: 256.2 | G37: 19.3 | H37: 195 | I37: 98.7
A38: Avril | B38: 157.5 | C38: 111.7 | D38: 113.2 | E38: 804.9 | F38: 242.4 | G38: 14.5 | H38: 175.5 | I38: 147.3
A39: Mai | B39: 151.2 | C39: 115.2 | D39: 115.9 | E39: 720.2 | F39: 233.5 | G39: 19 | H39: 156 | I39: 156.6
A40: Juin | B40: 141.4 | C40: 107 | D40: 112.6 | E40: 619 | F40: 237.4 | G40: 17.7 | H40: 130.5 | I40: 133.1
A41: Juillet | B41: 161.4 | C41: 117 | D41: 108 | E41: 605.4 | F41: 257.3 | G41: 14.8 | H41: 91.7 | I41: 104.1
A42: Août | B42: 168.3 | C42: 112.4 | D42: 107.8 | E42: 637.6 | F42: 281.7 | G42: 19 | H42: 96.2 | I42: 83.4
A43: Septembre | B43: 150.1 | C43: 119.1 | D43: 101.2 | E43: 960.9 | F43: 277.2 | G43: 15.7 | H43: 132.1 | I43: 77.2
A44: Octobre | B44: 153.3 | C44: 120.3 | D44: 125.5 | E44: 1315.1 | F44: 292.6 | G44: 15.6 | H44: 228 | I44: 61.7
A45: Novembre | B45: 156.8 | C45: 114.2 | D45: 125.8 | E45: 976.9 | F45: 279.1 | G45: 20.2 | H45: 186.8 | I45: 47.1
...

Sheet Catégories
A1: Catégories de médicaments
A2: Groupes rangés par catégorie grâce à leur code ATC. Les quantités de médicaments différents sont additionnées : à utiliser pour suivre une catégorie dans le temps, pas pour comparer deux catégories.
A3: ◀ Accueil
A5: CORRESPONDANCE CODE ATC → CATÉGORIE
A6: Code | B6: Sous-groupe ATC | C6: Catégorie | D6: Nouveau ?
A7: M01AB | B7: Dérivés de l'acide acétique (diclofénac) | C7: Douleur et inflammation | D7: Non
A8: M01AE | B8: Dérivés de l'acide propionique (ibuprofène) | C8: Douleur et inflammation | D8: Non
A9: N02BA | B9: Acide salicylique et dérivés (aspirine) | C9: Douleur et inflammation | D9: Non
A10: N02BE | B10: Anilides (paracétamol) | C10: Douleur et inflammation | D10: Non
A11: N05B | B11: Anxiolytiques | C11: Anxiété et sommeil | D11: Non
A12: N05C | B12: Hypnotiques et sédatifs | C12: Anxiété et sommeil | D12: Non
A13: R03 | B13: Médicaments de l'asthme et de la BPCO | C13: Respiratoire | D13: Non
A14: R06 | B14: Antihistaminiques | C14: Allergies | D14: Non
A17: VENTES MOYENNES PAR MOIS, PAR CATÉGORIE ET PAR ANNÉE
A18: Année | B18: Allergies | C18: Anxiété et sommeil | D18: Douleur et inflammation | E18: Respiratoire
A19: 2014 | B19: 69.3 | C19: 385.9 | D19: 1128 | E19: 103.7
A20: 2015 | B20: 83.4 | C20: 262.2 | D20: 1428.1 | E20: 147.7
A21: 2016 | B21: 89.7 | C21: 280.9 | D21: 1579.9 | E21: 179.4
A22: 2017 | B22: 81.1 | C22: 210.2 | D22: 1164.1 | E22: 158.2
A23: 2018 | B23: 101 | C23: 295.3 | D23: 1324.4 | E23: 225.5
A24: 2019 | B24: 119.5 | C24: 283.4 | D24: 1259 | E24: 213.6
A27: ÉVOLUTION SUR UN AN (12 DERNIERS MOIS COMPLETS CONTRE LES 12 PRÉCÉDENTS)
A28: Catégorie | B28: 12 derniers mois | C28: 12 mois précédents | D28: Évolution
A29: Allergies | B29: 1261.3 | C29: 1174.6 | D29: +7 %
A30: Anxiété et sommeil | B30: 3439.8 | C30: 3349 | D30: +3 %
A31: Douleur et inflammation | B31: 15928.4 | C31: 15598.7 | D31: +2 %
A32: Respiratoire | B32: 2962.7 | C32: 2323.2 | D32: +28 %
A35: NOUVEAUX MÉDICAMENTS DÉTECTÉS DANS CET EXPORT
A36: Code | B36: Catégorie
A37: Aucun | B37: L'export contient les mêmes 8 groupes qu'au départ.

Sheet État des données
A1: État des données
A3: ◀ Accueil
A5: QUEL EXPORT SERT À QUOI
A6: Export | B6: Lignes | C6: Début | D6: Fin | E6: Utilisation
A7: Pharma_Ventes_Hourly.csv | B7: 50532 | C7: 02/01/2014 | D7: 08/10/2019 | E7: Profil des ventes par heure uniquement
A8: Pharma_Ventes_Daily.csv | B8: 2106 | C8: 02/01/2014 | D8: 08/10/2019 | E8: RÉFÉRENCE : toutes les statistiques, l'onglet Ventes, les mois et semaines recalculés
A9: Pharma_Ventes_Weekly.csv | B9: 302 | C9: 05/01/2014 | D9: 13/10/2019 | E9: Contrôle de cohérence uniquement (identique au Daily regroupé)
A10: Pharma_Ventes_Monthly.csv | B10: 70 | C10: 31/01/2014 | D10: 31/10/2019 | E10: ÉCARTÉ : ne concorde pas avec les trois autres exports
A13: CE QUI A ÉTÉ CORRIGÉ OU ÉCARTÉ
A14: Corrigé ou écarté
A15: Export Monthly écarté : les mois sont recalculés à partir du Daily.
A16: Mois incomplets exclus de toutes les statistiques mensuelles et de la saisonnalité.
A17: Dernière ligne du Weekly (semaine incomplète) non utilisée.
A18: Colonne « Hour » du Daily ignorée ; année, mois et jour de semaine recalculés à partir de la date.
A19: Aucune valeur de vente modifiée : aucune ligne supprimée, aucun plafonnement.
A20: Unité des quantités non documentée par le logiciel de caisse : les groupes ne sont pas additionnés ni comparés en volume entre eux.
A23: RÉSULTAT DE CHAQUE CONTRÔLE
A24: Contrôle | B24: Résultat | C24: Statut
A25: Hourly : valeurs manquantes / dates en double / quantités négatives | B25: 0 / 0 / 0 | C25: OK
A26: Daily : valeurs manquantes / dates en double / quantités négatives | B26: 0 / 0 / 0 | C26: OK
A27: Weekly : valeurs manquantes / dates en double / quantités négatives | B27: 0 / 0 / 0 | C27: OK
A28: Monthly : valeurs manquantes / dates en double / quantités négatives | B28: 0 / 0 / 0 | C28: OK
A29: Daily : jours absents entre le premier et le dernier jour | B29: 0 | C29: OK
A30: Hourly : heures absentes entre la première et la dernière heure | B30: 0 | C30: OK
A31: Hourly regroupé par jour = Daily | B31: 0 jour(s) en écart sur 2106 | C31: OK
A32: Daily regroupé par semaine = Weekly | B32: 0 semaine(s) en écart sur 302 | C32: OK
A33: Daily regroupé par mois = Monthly | B33: 31 mois en écart sur 70 | C33: À noter
A34: Daily : colonne « Weekday Name » cohérente avec la date | B34: 0 ligne(s) incohérente(s) | C34: OK
A35: Daily : colonne « Hour » | B35: vaut 276 sur 2104 lignes sur 2106 : somme des heures, sans signification | C35: À noter
... A39: Quantités entières | B39: non : l'unité n'est pas la boîte | C39: À noter
A42: MOIS OÙ L'EXPORT MENSUEL NE CONCORDE PAS AVEC LES JOURS
A43: Mois | B43: Jours présents | C43: Complet | D43: Écart M01AB (Monthly - Daily) | E43: Écart M01AE (Monthly - Daily) | F43: Écart N02BA (Monthly - Daily) | G43: Écart N02BE (Monthly - Daily) | H43: Écart N05B (Monthly - Daily) | I43: Écart N05C (Monthly - Daily) | J43: Écart R03 (Monthly - Daily) | K43: Écart R06 (Monthly - Daily)
A44: 01/2014 | B44: 30 | C44: non | D44: 0 | E44: 0 | F44: 0 | G44: 0 | H44: 0 | I44: 20 | J44: 0 | K44: 0
A45: 04/2014 | B45: 30 | C45: oui | D45: 0 | E45: 0 | F45: 5.75 | G45: 0 | H45: 0 | I45: 0 | J45: 0 | K45: 0
A46: 08/2014 | B46: 31 | C46: oui | D46: 10 | E46: 0 | F46: 0 | G46: 36.5 | H46: 0 | I46: 0 | J46: 0 | K46: 0
A47: 09/2014 | B47: 30 | C47: oui | D47: 0 | E47: 0 | F47: 10 | G47: 0 | H47: 0 | I47: 0 | J47: 0 | K47: 0
A48: 10/2014 | B48: 31 | C48: oui | D48: 53.56 | E48: 76.49 | F48: 51.06 | G48: 783.68 | H48: 39.94 | I48: 10.38 | J48: 22 | K48: 27.81
A49: 03/2015 | B49: 31 | C49: oui | D49: 0 | E49: 0 | F49: 0 | G49: 0 | H49: 0 | I49: 0 | J49: 25 | K49: 0
A50: 06/2015 | B50: 30 | C50: oui | D50: 0 | E50: 0 | F50: 0 | G50: 31.38 | H50: 0 | I50: 0 | J50: 0 | K50: 0
A51: 11/2015 | B51: 30 | C51: oui | D51: 10 | E51: 0 | F51: 0 | G51: 42.75 | H51: 0 | I51: 0 | J51: 30 | K51: 0
...

Sheet Données
A1: Date | B1: M01AB | C1: M01AE | D1: N02BA | E1: N02BE | F1: N05B | G1: N05C | H1: R03 | I1: R06 | J1: Année | K1: Mois | L1: Jour
A2: 41641 | B2: 0 | C2: 3.67 | D2: 3.4 | E2: 32.4 | F2: 7 | G2: 0 | H2: 0 | I2: 2 | J2: 2014 | K2: 1 | L2: Jeudi
A3: 41642 | B3: 8 | C3: 4 | D3: 4.4 | E3: 50.6 | F3: 16 | G3: 0 | H3: 20 | I3: 4 | J3: 2014 | K3: 1 | L3: Vendredi
A4: 41643 | B4: 2 | C4: 1 | D4: 6.5 | E4: 61.85 | F4: 10 | G4: 0 | H4: 9 | I4: 1 | J4: 2014 | K4: 1 | L4: Samedi
A5: 41644 | B5: 4 | C5: 3 | D5: 7 | E5: 41.1 | F5: 8 | G5: 0 | H5: 3 | I5: 0 | J5: 2014 | K5: 1 | L5: Dimanche
A6: 41645 | B6: 5 | C6: 1 | D6: 4.5 | E6: 21.7 | F6: 16 | G6: 2 | H6: 6 | I6: 2 | J6: 2014 | K6: 1 | L6: Lundi
A7: 41646 | B7: 4.33 | C7: 0.66 | D7: 2.5 | E7: 37 | F7: 6 | G7: 0 | H7: 3 | I7: 4 | J7: 2014 | K7: 1 | L7: Mardi
A8: 41647 | B8: 5.33 | C8: 3 | D8: 10.5 | E8: 26.4 | F8: 19 | G8: 1 | H8: 10 | I8: 0 | J8: 2014 | K8: 1 | L8: Mercredi
A9: 41648 | B9: 7 | C9: 1.68 | D9: 8 | E9: 25 | F9: 16 | G9: 0 | H9: 3 | I9: 2 | J9: 2014 | K9: 1 | L9: Jeudi
A10: 41649 | B10: 5 | C10: 2 | D10: 2 | E10: 53.3 | F10: 15 | G10: 2 | H10: 0 | I10: 2 | J10: 2014 | K10: 1 | L10: Vendredi
A11: 41650 | B11: 5 | C11: 4.34 | D11: 10.4 | E11: 52.3 | F11: 14 | G11: 0 | H11: 1 | I11: 0.2 | J11: 2014 | K11: 1 | L11: Samedi
A12: 41651 | B12: 2 | C12: 0.66 | D12: 2.5 | E12: 12 | F12: 8 | G12: 0 | H12: 1 | I12: 1 | J12: 2014 | K12: 1 | L12: Dimanche
A13: 41652 | B13: 7.34 | C13: 7.66 | D13: 6.2 | E13: 52 | F13: 9 | G13: 0 | H13: 7 | I13: 1 | J13: 2014 | K13: 1 | L13: Lundi
... A2107: 43746 | B2107: 0.33 | C2107: 1.73 | D2107: 0.5 | E2107: 44.3 | F2107: 20 | G2107: 2 | H2107: 2 | I2107: 0 | J2107: 2019 | K2107: 10 | L2107: Mardi
